Workbook

Sheet Cover
A1: Coverage X — Management Forecast V51
A3: Model | B3: CoverageX Management Forecast
A4: Version | B4: V56 — Honest revenue composition (V50 baseline CPS + Mepco IAA recognition)
A5: Build date | B5: 2026-05-20
A6: Forecast horizon | B6: 2024A – 2030E (monthly granularity, 72 forward months)
A7: Anchor period | B7: LTM Sep-25 (CX Quarterly Consolidated Report 2025-9-30)
A8: Engine logic | B8: Vintage cohort survival, per V50 (cancel curve × monthly originations)
A9: Tax basis | B9: LLC pass-through (0%); normalized 21% C-corp in DCF only
A10: Currency / units | B10: USD
A12: WORKBOOK CONTENTS
A13: Cover | B13: This sheet
A14: Live Data | B14: FRED + Yahoo peer snapshot (refresh via refresh_live_data.py)
A15: Assumptions | B15: V50 driver structure + Live Data links — single source of truth
A16: Sources | B16: Citation table
A17: Cancel Curves | B17: Vintage cohort survival rates per product (CX, ASD, Home, Producer)
A18: CX Sales | B18: CX retail VSC engine
A19: ASD Sales | B19: ASD VSC channel engine
A20: Home Sales | B20: CX Home / HWS engine
A21: Producer Sales | B21: Third-party producer commission engine
A22: Mepco Outstanding | B22: IAA roll-forward by vintage (cross-collateralized)
A23: Marketing Budget | B23: Ad spend → leads → contracts by channel
A24: Ops Staffing | B24: Headcount per 1,000 active contracts; loaded comp
... A34: Audit Log | B34: Build history + tie-out checks
A36: COLOR LEGEND
A37: Hardcoded input
A38: Formula
A39: Link to Live Data / cross-sheet
A41: PROVENANCE
A42: V50 source: ~/Downloads/Amwest-CoverageX Data/Coverage X - Management Forecast V50.xlsx
A43: Q3 actuals: ~/Downloads/CoverageX Data/CX Quarterly Consolidated Report-2025-9-30.pdf
A44: Covenant tie-out: ~/Downloads/CoverageX Data/CNB - CoverageX_Covenant Worksheet Dec 31, 2025.xlsx
A45: Mepco terms: COVERAGE X & MEPCO PROG AG v6 (07/12/2025)

Sheet Live Data
A1: Live Data — Coverage X
A2: Auto-refreshed by GitHub Actions at 2026-10-15T15:38:46Z. Re-download from the published URL to get the latest.
A3: Last refreshed: 2026-10-15T15:38:46Z
A4: Metric | B4: Value | C4: Unit | D4: Source | E4: Series | F4: URL | G4: As-of | H4: Refreshed | I4: Prior | J4: Pct Chg | K4: Drift
A5: 10Y Treasury (Rf) | B5: 5.21 | C5: % | D5: FRED | E5: DGS10 | F5: https://fred.stlouisfed.org/series/DGS10 | G5: 2026-10-13 | H5: 2026-10-15T15:38:46Z | I5: 4.67 | J5: 0
A6: Fed Funds Upper | B6: 4 | C6: % | D6: FRED | E6: DFEDTARU | F6: https://fred.stlouisfed.org/series/DFEDTARU | G6: 2026-10-15 | H6: 2026-10-15T15:38:46Z | I6: 3.75 | J6: 0
A7: 10Y-2Y Spread | B7: 0.37 | C7: % | D7: FRED | E7: T10Y2Y | F7: https://fred.stlouisfed.org/series/T10Y2Y | G7: 2026-10-14 | H7: 2026-10-15T15:38:46Z | I7: 0.53 | J7: 0
A8: Auto sales SAAR | B8: 16.378 | C8: millions | D8: FRED | E8: TOTALSA | F8: https://fred.stlouisfed.org/series/TOTALSA | G8: 2026-09-01 | H8: 2026-10-15T15:38:46Z | I8: 16.696 | J8: 0
A9: CPI used cars/trucks | B9: 184.395 | C9: index | D9: FRED | E9: CUUR0000SETA02 | F9: https://fred.stlouisfed.org/series/CUUR0000SETA02 | G9: 2026-09-01 | H9: 2026-10-15T15:38:46Z | I9: 177.936 | J9: 0
A10: U Mich Consumer Sentiment | B10: 51.7 | C10: index | D10: FRED | E10: UMCSENT | F10: https://fred.stlouisfed.org/series/UMCSENT | G10: 2026-08-01 | H10: 2026-10-15T15:38:46Z | I10: 53.3 | J10: 0
A11: Unemployment rate | B11: 4.2 | C11: % | D11: FRED | E11: UNRATE | F11: https://fred.stlouisfed.org/series/UNRATE | G11: 2026-09-01 | H11: 2026-10-15T15:38:46Z | I11: 4.3 | J11: 0
A12: 30Y Mortgage Rate | B12: 7.4 | C12: % | D12: FRED | E12: MORTGAGE30US | F12: https://fred.stlouisfed.org/series/MORTGAGE30US | G12: 2026-10-08 | H12: 2026-10-15T15:38:46Z | I12: 6.51 | J12: 0
A13: Vehicle Miles Traveled (idx) | B13: 294124 | C13: index | D13: FRED | E13: TRFVOLUSM227NFWA | F13: https://fred.stlouisfed.org/series/TRFVOLUSM227NFWA | G13: 2026-08-01 | H13: 2026-10-15T15:38:46Z | I13: 283207 | J13: 0
A14: Light truck inventory (idx) | B14: 187.097 | C14: thousands | D14: FRED | E14: AUINSA | F14: https://fred.stlouisfed.org/series/AUINSA | G14: 2026-08-01 | H14: 2026-10-15T15:38:46Z | I14: 198.116 | J14: 0
A15: AutoLoanRate_48mo | B15: 7.47 | C15: % | D15: FRED | E15: TERMCBAUTO48NS | F15: https://fred.stlouisfed.org/series/TERMCBAUTO48NS | G15: 2026-08-01 | H15: 2026-10-15T15:38:46Z | I15: 7.36 | J15: 0
A16: PEERS (public comps — caveat: no exact match for private specialty F&I)
A17: Ticker | B17: Name | C17: Sector | D17: Mkt Cap ($M) | E17: EV ($M) | F17: P/E (TTM) | G17: P/E (Fwd) | H17: P/B | I17: EV/EBITDA | J17: EV/Revenue | K17: Beta | L17: Live Price
A18: AIZ | B18: Assurant, Inc. | C18: Financial Services | D18: 12707.483 | E18: 12993.483 | F18: 13.138832 | G18: 11.407976 | H18: 2.1704397 | I18: 254.85001 | J18: 0.987 | K18: 0.556 | L18: 280.565
A19: ALLY | B19: Ally Financial Inc. | C19: Financial Services | D19: 12521.467 | E19: 26923.467 | F19: 9.915049 | G19: 6.297889 | H19: 0.9452517 | I19: 42.860001 | J19: 3.502 | K19: 1.109 | L19: 37.59
A20: KMX | B20: CarMax Inc | C20: Consumer Cyclical | D20: 5143.8377 | E20: 23757.896 | F20: 21.589287 | G20: 12.983712 | H20: 0.8733446 | I20: 38.525002 | J20: 0.856 | K20: 1.184 | L20: 51.919998
A21: CACC | B21: Credit Acceptance Corporation | C21: Financial Services | D21: 5731.3869 | E21: 12114.287 | F21: 13.660683 | G21: 10.018833 | H21: 3.7719598 | I21: 547.39001 | J21: 9.496 | K21: 1.358 | L21: 545.67999
A22: COF | B22: Capital One Financial Corporati | C22: Financial Services | D22: 113275.96 | E22: 95171.953 | F22: 55.83742 | G22: 7.539235 | H22: 1.049134 | I22: 185.88 | J22: 2.621 | K22: 1.05 | L22: 196.34
A24: Median | D24: =IFERROR(MEDIAN(D18:D22),"") | E24: =IFERROR(MEDIAN(E18:E22),"") | F24: =IFERROR(MEDIAN(F18:F22),"") | G24: =IFERROR(MEDIAN(G18:G22),"") | H24: =IFERROR(MEDIAN(H18:H22),"") | I24: =IFERROR(MEDIAN(I18:I22),"") | J24: =IFERROR(MEDIAN(J18:J22),"") | K24: =IFERROR(MEDIAN(K18:K22),"")
A25: Mean | D25: =IFERROR(AVERAGE(D18:D22),"") | E25: =IFERROR(AVERAGE(E18:E22),"") | F25: =IFERROR(AVERAGE(F18:F22),"") | G25: =IFERROR(AVERAGE(G18:G22),"") | H25: =IFERROR(AVERAGE(H18:H22),"") | I25: =IFERROR(AVERAGE(I18:I22),"") | J25: =IFERROR(AVERAGE(J18:J22),"") | K25: =IFERROR(AVERAGE(K18:K22),"")

Sheet Assumptions
A1: Assumptions — V56 (final; IAA gross/net dual-documentation)
A2: Hardcoded blue. Live Data links green. Salt-and-pepper layout matches V50 for diff-ability.
A4: CORE OPERATING ASSUMPTIONS (V50 structure preserved)
A5: Corporate Tax Rate (Fed & State) | B5: 0
A6: Investor Distributions — threshold ($) | B6: 1000000000
A7: Investor Distributions — start month | B7: 12
A8: Accounts Receivable (days) | B8: 30
A9: Annual Increase — Contracts | B9: 0.03 | D9: Price escalator
A10: Annual Increase — All Else | B10: 0.03
A11: Annual Increase — Salaries | B11: 0.03
A12: Payroll Taxes | B12: 0.15
A13: Benefits | B13: 0.2
A16: CONTRACT TERMS — Coverage X
A17: Avg Monthly Customer Payment ($) | B17: 125 | D17: Calibrated to FY 2025 subscription revenue actual ($118.7M)
A18: Advanced Customer Payments (months) | B18: 8
A19: Mepco IAA per contract — derived ($) | B19: =B17*B18
A20: Insurance Premium — upfront ($) | B20: 12 | D20: Sourced from FY 2025 actual $1.2M / ~100K new contracts
A21: Insurance Premium — after cancel ($) | B21: 50
A22: PB Reserve (Mepco) per New Contract ($) | B22: 0
A23: Cancel Curve Improvement | B23: 0.2 | D23: PRIMARY STICK-RATE LEVER — higher = contracts last longer
A24: Claims Reserve Account ($/contract) | B24: 150
A25: Actual Claims Expense Start (month #) | B25: 12
A26: Charge Back rate | B26: 0.025
A27: Merchant Fees | B27: 0.035
A28: Merchant Reserve | B28: 0.035
A29: Contract Fulfillment — Postage ($) | B29: 1.83
A30: Contract Fulfillment — Printing ($) | B30: 1
A32: Initiation fee per new contract ($) | B32: 64 | D32: Sourced from FY 2025 Q4 PDF: $5.16M init fee / ~100K new contracts
A33: MEPCO PROGRAMME AGREEMENT v6 (07/12/2025)
A34: Mepco IAA per contract — gross programme value (revenue recognition basis, ASC 606) | B34: 1450 | D34: Per Programme Agreement; differs from V50 derived
A35: Mepco PB premium (% IAA) | B35: 0.06 | D35: 6% per Programme Agreement
A36: PB Period (months) | B36: 24
A37: Earliest claim filing (month) | B37: 26
A38: Producer commission per contract ($) | B38: 500
A39: Funding cadence | B39: Weekly (Thursday)
A40: Mepco reserve release at CNB loan close | B40: 10000000
A42: CHANNEL SPECIFICS — ASD & Producer
A43: ASD Increase Sales per Month | B43: 100
A44: Producer Increase Sales per Month | B44: 150
A45: Producer Fulfillment — Postage ($) | B45: 1.77
...

Sheet Sources
A1: Sources & Data Lineage
A2: One row per source. Last Refresh updated by refresh_live_data.py.
A4: Source | B4: Type | C4: Identifier | D4: URL / Path | E4: Used in | F4: Last Refresh
A5: V50 — Coverage X Management Forecast | B5: Internal | C5: V50.xlsx | D5: ~/Downloads/Amwest-CoverageX Data/ | E5: Cancel curve, monthly contracts, unit econ | F5: static (V50)
A6: FRED — 10Y Treasury | B6: Macro | C6: DGS10 | D6: https://fred.stlouisfed.org/series/DGS10 | E6: Live Data; Assumptions Rf; WACC | F6: 2026-05-20 03:20 UTC
A7: FRED — Fed Funds Upper | B7: Macro | C7: DFEDTARU | D7: https://fred.stlouisfed.org/series/DFEDTARU | E7: Live Data | F7: 2026-05-20 03:20 UTC
A8: FRED — 10Y-2Y Spread | B8: Macro | C8: T10Y2Y | D8: https://fred.stlouisfed.org/series/T10Y2Y | E8: Live Data; recession context | F8: 2026-05-20 03:20 UTC
A9: FRED — Auto SAAR | B9: Macro | C9: TOTALSA | D9: https://fred.stlouisfed.org/series/TOTALSA | E9: Live Data; auto market context | F9: 2026-05-20 03:20 UTC
A10: FRED — Used Vehicle CPI | B10: Macro | C10: CUUR0000SETA02 | D10: https://fred.stlouisfed.org/series/CUUR0000SETA02 | E10: Live Data; VSC value proxy | F10: 2026-05-20 03:20 UTC
A11: FRED — U Mich Sentiment | B11: Macro | C11: UMCSENT | D11: https://fred.stlouisfed.org/series/UMCSENT | E11: Live Data; consumer demand | F11: 2026-05-20 03:20 UTC
A12: FRED — Unemployment Rate | B12: Macro | C12: UNRATE | D12: https://fred.stlouisfed.org/series/UNRATE | E12: Live Data; cancel curve sensitivity | F12: 2026-05-20 03:20 UTC
A13: FRED — 30Y Mortgage Rate | B13: Macro | C13: MORTGAGE30US | D13: https://fred.stlouisfed.org/series/MORTGAGE30US | E13: Live Data; cross-product context | F13: 2026-05-20 03:20 UTC
A14: FRED — Vehicle Miles Traveled | B14: Macro | C14: TRFVOLUSM227NFWA | D14: https://fred.stlouisfed.org/series/TRFVOLUSM227NFWA | E14: Live Data; VSC usage proxy | F14: 2026-05-20 03:20 UTC
A15: Yahoo Finance — AIZ | B15: Peer | C15: AIZ | D15: https://finance.yahoo.com/quote/AIZ | E15: Live Data; Trading Comps | F15: 2026-05-20 03:20 UTC
... A24: CNB Contract Insurance Endorsements (Add 2/3/4) | B24: Legal | C24: 2023-2024 | D24: ~/Downloads/CoverageX Data/ | E24: Insurance premium structure context | F24: static

Sheet Cancel Curves
A1: Cancel Curves — Vintage Cohort Survival by Product
A2: Source: V50 cancel curve + improvement factor from Assumptions!B23. Same curve applied to all 4 products in V50.
A4: A. Cancel rates by month-since-origination (raw — pre-improvement)
A5: Month # | B5: 1 | C5: 2 | D5: 3 | E5: 4 | F5: 5 | G5: 6 | H5: 7 | I5: 8 | J5: 9 | K5: 10 | L5: 11 | M5: 12 | N5: 13 | O5: 14 | P5: 15 | Q5: 16 | R5: 17 | S5: 18 | T5: 19 | U5: 20 | V5: 21 | W5: 22 | X5: 23 | Y5: 24 | Z5: 25 | AA5: 26 | AB5: 27 | AC5: 28 | AD5: 29 | AE5: 30 | AF5: 31 | AG5: 32 | AH5: 33 | AI5: 34 | AJ5: 35 | AK5: 36 | AL5: 37 | AM5: 38 | AN5: 39 | AO5: 40 | AP5: 41 | AQ5: 42 | AR5: 43 | AS5: 44 | AT5: 45 | AU5: 46 | AV5: 47 | AW5: 48 | AX5: 49 | AY5: 50 | AZ5: 51 | BA5: 52 | BB5: 53 | BC5: 54 | BD5: 55 | BE5: 56 | BF5: 57 | BG5: 58 | BH5: 59 | BI5: 60 | BJ5: 61 | BK5: 62 | BL5: 63 | BM5: 64 | BN5: 65 | BO5: 66 | BP5: 67 | BQ5: 68 | BR5: 69 | BS5: 70 | BT5: 71
A6: Cancel rate (raw) | B6: 0.28 | C6: 0.13 | D6: 0.1 | E6: 0.08 | F6: 0.07 | G6: 0.06 | H6: 0.06 | I6: 0.05 | J6: 0.05 | K6: 0.05 | L6: 0.04 | M6: 0.04 | N6: 0.04 | O6: 0.03 | P6: 0.03 | Q6: 0.03 | R6: 0.02 | S6: 0.02 | T6: 0.02 | U6: 0.02 | V6: 0.02 | W6: 0.02 | X6: 0.02 | Y6: 0.01 | Z6: 0.01 | AA6: 0.01 | AB6: 0.01 | AC6: 0.01 | AD6: 0.01 | AE6: 1 | AF6: 1 | AG6: 1 | AH6: 1 | AI6: 1 | AJ6: 1 | AK6: 1 | AL6: 1 | AM6: 1 | AN6: 1 | AO6: 1 | AP6: 1 | AQ6: 1 | AR6: 1 | AS6: 1 | AT6: 1 | AU6: 1 | AV6: 1 | AW6: 1 | AX6: 1 | AY6: 1 | AZ6: 1 | BA6: 1 | BB6: 1 | BC6: 1 | BD6: 1 | BE6: 1 | BF6: 1 | BG6: 1 | BH6: 1 | BI6: 1 | BJ6: 1 | BK6: 1 | BL6: 1 | BM6: 1 | BN6: 1 | BO6: 1 | BP6: 1 | BQ6: 1 | BR6: 1 | BS6: 1 | BT6: 1
A8: B. Adjusted cancel rate (raw × (1 − improvement factor))
A9: Adjusted cancel | B9: =B6*(1-Assumptions!$B$23) | C9: =C6*(1-Assumptions!$B$23) | D9: =D6*(1-Assumptions!$B$23) | E9: =E6*(1-Assumptions!$B$23) | F9: =F6*(1-Assumptions!$B$23) | G9: =G6*(1-Assumptions!$B$23) | H9: =H6*(1-Assumptions!$B$23) | I9: =I6*(1-Assumptions!$B$23) | ... BT9: =BT6*(1-Assumptions!$B$23)
A11: C. Survival rate (Π_{k=0..n} (1 - adjusted_k))
A12: Survival | B12: 1 | C12: =B12*(1-B9) | D12: =C12*(1-C9) | E12: =D12*(1-D9) | F12: =E12*(1-E9) | G12: =F12*(1-F9) | H12: =G12*(1-G9) | I12: =H12*(1-H9) | J12: =I12*(1-I9) | ... BT12: =BS12*(1-BS9)
A14: Avg months/contract | B14: =SUM(B12:BT12)
A16: Curve length: 71 months. Month 30+ = full cancel per V50.
A17: Survival vector is referenced by all 4 product engines (CX/ASD/Home/Producer).
A18: V50 applied one shared curve to all products. V51 preserves this behavior.

Sheet CX Sales
A1: CX Retail VSC — Engine (Vintage Cohort Survival)
A2: Monthly originations × shared cancel curve. CPS (customer payment per service) = $100.0/mo.
C3: 2024A | D3: 2025 | E3: 2025 | F3: 2025 | G3: 2025 | H3: 2025 | I3: 2025 | J3: 2025 | K3: 2025 | L3: 2025 | M3: 2025 | N3: 2025 | O3: 2025 | P3: 2026 | Q3: 2026 | R3: 2026 | S3: 2026 | T3: 2026 | U3: 2026 | V3: 2026 | W3: 2026 | X3: 2026 | Y3: 2026 | Z3: 2026 | AA3: 2026 | AB3: 2027 | AC3: 2027 | AD3: 2027 | AE3: 2027 | AF3: 2027 | AG3: 2027 | AH3: 2027 | AI3: 2027 | AJ3: 2027 | AK3: 2027 | AL3: 2027 | AM3: 2027 | AN3: 2028 | AO3: 2028 | AP3: 2028 | AQ3: 2028 | AR3: 2028 | AS3: 2028 | AT3: 2028 | AU3: 2028 | AV3: 2028 | AW3: 2028 | AX3: 2028 | AY3: 2028 | AZ3: 2029 | BA3: 2029 | BB3: 2029 | BC3: 2029 | BD3: 2029 | BE3: 2029 | BF3: 2029 | BG3: 2029 | BH3: 2029 | BI3: 2029 | BJ3: 2029 | BK3: 2029 | BL3: 2030 | BM3: 2030 | BN3: 2030 | BO3: 2030 | BP3: 2030 | BQ3: 2030 | BR3: 2030 | BS3: 2030 | BT3: 2030 | BU3: 2030 | BV3: 2030 | BW3: 2030
C4: Anchor | D4: 2025-01 | E4: 2025-02 | F4: 2025-03 | G4: 2025-04 | H4: 2025-05 | I4: 2025-06 | J4: 2025-07 | K4: 2025-08 | L4: 2025-09 | M4: 2025-10 | N4: 2025-11 | O4: 2025-12 | P4: 2026-01 | Q4: 2026-02 | R4: 2026-03 | S4: 2026-04 | T4: 2026-05 | U4: 2026-06 | V4: 2026-07 | W4: 2026-08 | X4: 2026-09 | Y4: 2026-10 | Z4: 2026-11 | AA4: 2026-12 | AB4: 2027-01 | AC4: 2027-02 | AD4: 2027-03 | AE4: 2027-04 | AF4: 2027-05 | AG4: 2027-06 | AH4: 2027-07 | AI4: 2027-08 | AJ4: 2027-09 | AK4: 2027-10 | AL4: 2027-11 | AM4: 2027-12 | AN4: 2028-01 | AO4: 2028-02 | AP4: 2028-03 | AQ4: 2028-04 | AR4: 2028-05 | AS4: 2028-06 | AT4: 2028-07 | AU4: 2028-08 | AV4: 2028-09 | AW4: 2028-10 | AX4: 2028-11 | AY4: 2028-12 | AZ4: 2029-01 | BA4: 2029-02 | BB4: 2029-03 | BC4: 2029-04 | BD4: 2029-05 | BE4: 2029-06 | BF4: 2029-07 | BG4: 2029-08 | BH4: 2029-09 | BI4: 2029-10 | BJ4: 2029-11 | BK4: 2029-12 | BL4: 2030-01 | BM4: 2030-02 | BN4: 2030-03 | BO4: 2030-04 | BP4: 2030-05 | BQ4: 2030-06 | BR4: 2030-07 | BS4: 2030-08 | BT4: 2030-09 | BU4: 2030-10 | BV4: 2030-11 | BW4: 2030-12
A5: New contracts originated | D5: 959 | E5: 806 | F5: 1103 | G5: 1857 | H5: 2500 | I5: 2500 | J5: 2500 | K5: 2500 | L5: 2400 | M5: 2500 | N5: 2750 | O5: 3000 | P5: 3500 | Q5: 4000 | R5: 4500 | S5: 5000 | T5: 5500 | U5: 6000 | V5: 6500 | W5: 7000 | X5: 7500 | Y5: 8000 | Z5: 8500 | AA5: 9000 | AB5: 9250 | AC5: 9500 | AD5: 9750 | AE5: 10000 | AF5: 10250 | AG5: 10500 | AH5: 10750 | AI5: 11000 | AJ5: 11250 | AK5: 11500 | AL5: 11750 | AM5: 12000 | AN5: 12250 | AO5: 12500 | AP5: 12750 | AQ5: 13000 | AR5: 13250 | AS5: 13500 | AT5: 13750 | AU5: 14000 | AV5: 14250 | AW5: 14500 | AX5: 14750 | AY5: 15000 | AZ5: 15250 | BA5: 15500 | BB5: 15750 | BC5: 16000 | BD5: 16250 | BE5: 16500 | BF5: 16750 | BG5: 17000 | BH5: 17250 | BI5: 17500 | BJ5: 17750 | BK5: 18000 | BL5: 18250 | BM5: 18500 | BN5: 18750 | BO5: 19000 | BP5: 19250 | BQ5: 19500 | BR5: 19750 | BS5: 20000 | BT5: 20250 | BU5: 20500 | BV5: 20750 | BW5: 21000
